<?xml version="1.0" ?>
<!-- =================================================================================== -->
<!-- |    This document was autogenerated by xacro from /home/main/catkin_ws/src/fmauch_universal_robot/ur_e_description/urdf/ur5e_robot.urdf.xacro | -->
<!-- |    EDITING THIS FILE BY HAND IS NOT RECOMMENDED                                 | -->
<!-- =================================================================================== -->
<robot name="ur5e" xmlns:xacro="http://ros.org/wiki/xacro">
  <gazebo>
    <plugin filename="libgazebo_ros_control.so" name="ros_control">
      <!--robotNamespace>/</robotNamespace-->
      <!--robotSimType>gazebo_ros_control/DefaultRobotHWSim</robotSimType-->
    </plugin>
    <!--
    <plugin name="gazebo_ros_power_monitor_controller" filename="libgazebo_ros_power_monitor.so">
      <alwaysOn>true</alwaysOn>
      <updateRate>1.0</updateRate>
      <timeout>5</timeout>
      <powerStateTopic>power_state</powerStateTopic>
      <powerStateRate>10.0</powerStateRate>
      <fullChargeCapacity>87.78</fullChargeCapacity>
      <dischargeRate>-474</dischargeRate>
      <chargeRate>525</chargeRate>
      <dischargeVoltage>15.52</dischargeVoltage>
      <chargeVoltage>16.41</chargeVoltage>
    </plugin>
-->
  </gazebo>
  <!-- measured from model -->
  <!-- link lengths used in model -->
  <!-- manually measured -->
  <link name="mount_base"/>
  <joint name="y_gantry" type="fixed">
    <parent link="mount_base"/>
    <child link="mount"/>
    <origin rpy="0.0 0.0 0.0" xyz="0.0 0.0 0.0"/>
    <axis xyz="0 1 0"/>
    <limit effort="330.0" lower="-0.25" upper="0.25" velocity="0.2"/>
    <dynamics damping="0.0" friction="0.0"/>
  </joint>
  <link name="mount">
    <visual>
<!--	  <origin rpy="0.0 0.0 0.0" xyz="-0.02 0.0 0.0"/>-->
	  <origin rpy="0.0 0.0 0.0" xyz="0 0.0 0.375"/>
      <geometry>
<!--        <box size="0.04 0.5 0.5"/>-->
        <box size="0.5 0.5 0.75"/>
      </geometry>
      <material name="LightGrey">
        <color rgba="0.7 0.7 0.7 1.0"/>
      </material>
    </visual>
    <collision>
<!--	  <origin rpy="0.0 0.0 0.0" xyz="-0.02 0.0 0.0"/>-->
	  <origin rpy="0.0 0.0 0.0" xyz="0 0.0 -0.02"/>
      <geometry>
<!--        <box size="0.04 0.5 0.5"/>-->
        <box size="0.5 0.5 0.75"/>
      </geometry>
    </collision>
    <inertial>
      <mass value="4.0"/>
      <origin rpy="0 0 0" xyz="0.0 0.0 0.0"/>
      <inertia ixx="0.006106" ixy="0.0" ixz="0.0" iyy="0.006106" iyz="0.0" izz="0.01125"/>
    </inertial>
  </link>
  <joint name="mount_base_joint" type="fixed">
    <parent link="mount"/>
    <child link="base_link"/>
<!--    <origin rpy="0.0 1.570796 0.0" xyz="0.0 0.0 0.0"/>-->
    <origin rpy="0.0 0.0 0.0" xyz="0.0 0.0 0.75"/>
    <axis xyz="0 0 1"/>
  </joint>
  <link name="base_link">
    <visual>
      <origin rpy="0 0 3.14159265359" xyz="0 0 0"/>
      <geometry>
        <mesh filename="/home/main/python/pybullet/robots/ur5e/visual/base.dae"/>
      </geometry>
      <material name="LightGrey">
        <color rgba="0.7 0.7 0.7 1.0"/>
      </material>
    </visual>
    <collision>
      <origin rpy="0 0 3.14159265359" xyz="0 0 0"/>
      <geometry>
        <mesh filename="/home/main/python/pybullet/robots/ur5e/collision/base.stl"/>
      </geometry>
    </collision>
    <inertial>
      <mass value="4.0"/>
      <origin rpy="0 0 0" xyz="0.0 0.0 0.0"/>
      <inertia ixx="0.00443333156" ixy="0.0" ixz="0.0" iyy="0.00443333156" iyz="0.0" izz="0.0072"/>
    </inertial>
  </link>
  <joint name="shoulder_pan_joint" type="revolute">
    <parent link="base_link"/>
    <child link="shoulder_link"/>
    <origin rpy="0 0 3.14159265774" xyz="0 0 0.162509611124"/>
    <axis xyz="0 0 1"/>
    <limit effort="150.0" lower="-6.28318530718" upper="6.28318530718" velocity="3.14"/>
    <dynamics damping="0.0" friction="0.0"/>
  </joint>
  <link name="shoulder_link">
    <visual>
      <origin rpy="0 0 3.14159265359" xyz="0 0 0"/>
      <geometry>
        <mesh filename="/home/main/python/pybullet/robots/ur5e/visual/shoulder.dae"/>
      </geometry>
      <material name="LightGrey">
        <color rgba="0.7 0.7 0.7 1.0"/>
      </material>
    </visual>
    <collision>
      <origin rpy="0 0 3.14159265359" xyz="0 0 0"/>
      <geometry>
        <mesh filename="/home/main/python/pybullet/robots/ur5e/collision/shoulder.stl"/>
      </geometry>
    </collision>
    <inertial>
      <mass value="3.7"/>
      <origin rpy="0 0 0" xyz="0.0 0.0 0.0"/>
      <inertia ixx="0.010267495893" ixy="0.0" ixz="0.0" iyy="0.010267495893" iyz="0.0" izz="0.00666"/>
    </inertial>
  </link>
  <joint name="shoulder_lift_joint" type="revolute">
    <parent link="shoulder_link"/>
    <child link="upper_arm_link"/>
    <origin rpy="1.57201212277 0 -4.22293331334e-06" xyz="0.000175875481034 0 0"/>
    <axis xyz="0 0 1"/>
    <limit effort="150.0" lower="-6.28318530718" upper="6.28318530718" velocity="3.14"/>
    <dynamics damping="0.0" friction="0.0"/>
  </joint>
  <link name="upper_arm_link">
    <visual>
      <origin rpy="1.57079632679 0 -1.57079632679" xyz="0 0 0.138"/>
      <geometry>
        <mesh filename="/home/main/python/pybullet/robots/ur5e/visual/upperarm.dae"/>
      </geometry>
      <material name="LightGrey">
        <color rgba="0.7 0.7 0.7 1.0"/>
      </material>
    </visual>
    <collision>
      <origin rpy="1.57079632679 0 -1.57079632679" xyz="0 0 0.138"/>
      <geometry>
        <mesh filename="/home/main/python/pybullet/robots/ur5e/collision/upperarm.stl"/>
      </geometry>
    </collision>
    <inertial>
      <mass value="8.393"/>
      <origin rpy="0 1.57079632679 0" xyz="-0.212641211079 0.0 0.138"/>
      <inertia ixx="0.138302693282" ixy="0.0" ixz="0.0" iyy="0.138302693282" iyz="0.0" izz="0.0236053125"/>
    </inertial>
  </link>
  <joint name="elbow_joint" type="revolute">
    <parent link="upper_arm_link"/>
    <child link="forearm_link"/>
    <origin rpy="3.14087106174 3.14130791395 -3.1415908958" xyz="-0.425282422158 0 0"/>
    <axis xyz="0 0 1"/>
    <limit effort="150.0" lower="-3.14159265359" upper="3.14159265359" velocity="3.14"/>
    <dynamics damping="0.0" friction="0.0"/>
  </joint>
  <link name="forearm_link">
    <visual>
      <origin rpy="1.57079632679 0 -1.57079632679" xyz="0 0 0.007"/>
      <geometry>
        <mesh filename="/home/main/python/pybullet/robots/ur5e/visual/forearm.dae"/>
      </geometry>
      <material name="LightGrey">
        <color rgba="0.7 0.7 0.7 1.0"/>
      </material>
    </visual>
    <collision>
      <origin rpy="1.57079632679 0 -1.57079632679" xyz="0 0 0.007"/>
      <geometry>
        <mesh filename="/home/main/python/pybullet/robots/ur5e/collision/forearm.stl"/>
      </geometry>
    </collision>
    <inertial>
      <mass value="2.275"/>
      <origin rpy="0 1.57079632679 0" xyz="-0.212641211079 0.0 0.007"/>
      <inertia ixx="0.032394493594" ixy="0.0" ixz="0.0" iyy="0.032394493594" iyz="0.0" izz="0.0063984375"/>
    </inertial>
  </link>
  <joint name="wrist_1_joint" type="revolute">
    <parent link="forearm_link"/>
    <child link="wrist_1_link"/>
    <origin rpy="3.13857728923 -3.14158422042 3.14159213673" xyz="-0.392424671078 0.000403177258085 0.13370723674"/>
    <axis xyz="0 0 1"/>
    <limit effort="28.0" lower="-6.28318530718" upper="6.28318530718" velocity="6.28"/>
    <dynamics damping="0.0" friction="0.0"/>
  </joint>
  <link name="wrist_1_link">
    <visual>
      <origin rpy="1.57079632679 0 0" xyz="0 0 -0.127"/>
      <geometry>
        <mesh filename="/home/main/python/pybullet/robots/ur5e/visual/wrist1.dae"/>
      </geometry>
      <material name="LightGrey">
        <color rgba="0.7 0.7 0.7 1.0"/>
      </material>
    </visual>
    <collision>
      <origin rpy="1.57079632679 0 0" xyz="0 0 -0.127"/>
      <geometry>
        <mesh filename="/home/main/python/pybullet/robots/ur5e/collision/wrist1.stl"/>
      </geometry>
    </collision>
    <inertial>
      <mass value="1.219"/>
      <origin rpy="0 0 0" xyz="0.0 0.0 0.0"/>
      <inertia ixx="0.00272544945219" ixy="0.0" ixz="0.0" iyy="0.00272544945219" iyz="0.0" izz="0.0034284375"/>
    </inertial>
  </link>
  <joint name="wrist_2_joint" type="revolute">
    <parent link="wrist_1_link"/>
    <child link="wrist_2_link"/>
    <origin rpy="1.57047823229 0 -1.22657964634e-06" xyz="-3.59538768323e-05 -0.0997732519853 3.17373243326e-05"/>
    <axis xyz="0 0 1"/>
    <limit effort="28.0" lower="-6.28318530718" upper="6.28318530718" velocity="6.28"/>
    <dynamics damping="0.0" friction="0.0"/>
  </joint>
  <link name="wrist_2_link">
    <visual>
      <origin rpy="0 0 0" xyz="0 0 -0.0997"/>
      <geometry>
        <mesh filename="/home/main/python/pybullet/robots/ur5e/visual/wrist2.dae"/>
      </geometry>
      <material name="LightGrey">
        <color rgba="0.7 0.7 0.7 1.0"/>
      </material>
    </visual>
    <collision>
      <origin rpy="0 0 0" xyz="0 0 -0.0997"/>
      <geometry>
        <mesh filename="/home/main/python/pybullet/robots/ur5e/collision/wrist2.stl"/>
      </geometry>
    </collision>
    <inertial>
      <mass value="1.219"/>
      <origin rpy="0 0 0" xyz="0.0 0.0 0.0"/>
      <inertia ixx="0.00271885242747" ixy="0.0" ixz="0.0" iyy="0.00271885242747" iyz="0.0" izz="0.0034284375"/>
    </inertial>
  </link>
  <joint name="wrist_3_joint" type="revolute">
    <parent link="wrist_2_link"/>
    <child link="wrist_3_link"/>
    <origin rpy="1.57172710837 3.14159265359 3.14159251741" xyz="5.59741171522e-05 0.0994472713895 9.25637146449e-05"/>
    <axis xyz="0 0 1"/>
    <limit effort="28.0" lower="-6.28318530718" upper="6.28318530718" velocity="6.28"/>
    <dynamics damping="0.0" friction="0.0"/>
  </joint>
  <link name="wrist_3_link">
    <visual>
      <origin rpy="1.57079632679 0 0" xyz="0 0 -0.0989"/>
      <geometry>
        <mesh filename="/home/main/python/pybullet/robots/ur5e/visual/wrist3.dae"/>
      </geometry>
      <material name="LightGrey">
        <color rgba="0.7 0.7 0.7 1.0"/>
      </material>
    </visual>
    <collision>
      <origin rpy="1.57079632679 0 0" xyz="0 0 -0.0989"/>
      <geometry>
        <mesh filename="/home/main/python/pybullet/robots/ur5e/collision/wrist3.stl"/>
      </geometry>
    </collision>
    <inertial>
      <mass value="0.1879"/>
      <origin rpy="0 0 0" xyz="0.0 0.0 -0.025"/>
      <inertia ixx="0.000134270154625" ixy="0.0" ixz="0.0" iyy="0.000134270154625" iyz="0.0" izz="0.00019024875"/>
    </inertial>
  </link>
  <joint name="ee_fixed_joint" type="fixed">
    <parent link="wrist_3_link"/>
    <child link="ee_link"/>
    <origin rpy="0.0 -1.57079632679 1.57079632679" xyz="0.0 0.0 0.0"/>
  </joint>
  <link name="ee_link">
    <collision>
      <geometry>
        <box size="0.01 0.01 0.01"/>
      </geometry>
      <origin rpy="0 0 0" xyz="-0.01 0 0"/>
    </collision>
  </link>
  <transmission name="shoulder_pan_trans">
    <type>transmission_interface/SimpleTransmission</type>
    <joint name="shoulder_pan_joint">
      <hardwareInterface>hardware_interface/PositionJointInterface</hardwareInterface>
    </joint>
    <actuator name="shoulder_pan_motor">
      <mechanicalReduction>1</mechanicalReduction>
    </actuator>
  </transmission>
  <transmission name="shoulder_lift_trans">
    <type>transmission_interface/SimpleTransmission</type>
    <joint name="shoulder_lift_joint">
      <hardwareInterface>hardware_interface/PositionJointInterface</hardwareInterface>
    </joint>
    <actuator name="shoulder_lift_motor">
      <mechanicalReduction>1</mechanicalReduction>
    </actuator>
  </transmission>
  <transmission name="elbow_trans">
    <type>transmission_interface/SimpleTransmission</type>
    <joint name="elbow_joint">
      <hardwareInterface>hardware_interface/PositionJointInterface</hardwareInterface>
    </joint>
    <actuator name="elbow_motor">
      <mechanicalReduction>1</mechanicalReduction>
    </actuator>
  </transmission>
  <transmission name="wrist_1_trans">
    <type>transmission_interface/SimpleTransmission</type>
    <joint name="wrist_1_joint">
      <hardwareInterface>hardware_interface/PositionJointInterface</hardwareInterface>
    </joint>
    <actuator name="wrist_1_motor">
      <mechanicalReduction>1</mechanicalReduction>
    </actuator>
  </transmission>
  <transmission name="wrist_2_trans">
    <type>transmission_interface/SimpleTransmission</type>
    <joint name="wrist_2_joint">
      <hardwareInterface>hardware_interface/PositionJointInterface</hardwareInterface>
    </joint>
    <actuator name="wrist_2_motor">
      <mechanicalReduction>1</mechanicalReduction>
    </actuator>
  </transmission>
  <transmission name="wrist_3_trans">
    <type>transmission_interface/SimpleTransmission</type>
    <joint name="wrist_3_joint">
      <hardwareInterface>hardware_interface/PositionJointInterface</hardwareInterface>
    </joint>
    <actuator name="wrist_3_motor">
      <mechanicalReduction>1</mechanicalReduction>
    </actuator>
  </transmission>

  <!-- ROS base_link to UR 'Base' Coordinates transform -->
  <link name="base"/>
  <joint name="base_link-base_fixed_joint" type="fixed">
    <!-- NOTE: this rotation is only needed as long as base_link itself is
                 not corrected wrt the real robot (ie: rotated over 180
                 degrees)
      -->
    <origin rpy="0 0 -3.14159265359" xyz="0 0 0"/>
    <parent link="base_link"/>
    <child link="base"/>
  </joint>
  <!-- Frame coincident with all-zeros TCP on UR controller -->
  <link name="tool0"/>
  <joint name="wrist_3_link-tool0_fixed_joint" type="fixed">
    <origin rpy="0 0 0" xyz="0 0 0"/>
    <parent link="wrist_3_link"/>
    <child link="tool0"/>
  </joint>

  <link name="camera_mount">
    <visual>
      <origin rpy="0 0 0" xyz="0 0 0"/>
      <geometry>
        <mesh filename="/home/main/python/pybullet/robots/ur5e/visual/camera_mount.dae" scale="1.0 1.0 1.0"/>
      </geometry>
      <material name="LightGrey"/>
    </visual>
    <!-- Camera collision -->

        <collision>
          <origin rpy="0 0 0" xyz="0 0.0725 0.025" />
          <geometry>
            <box size="0.121 0.060 0.050" />
          </geometry>
        </collision>
        <inertial>
      <origin rpy="0 0 0" xyz="1.0E-08 1.0E-08 1.0E-08"/>
      <mass value="1.0E-08"/>
      <inertia ixx="1.0E-08" ixy="1.0E-08" ixz="1.0E-08" iyy="1.0E-08" iyz="1.0E-08" izz="1.0E-08"/>
    </inertial>
  </link>

  <joint name="camera_mount" type="fixed">
      <origin rpy="0 0 0" xyz="0 0 0"/>
    <axis xyz="0 0 1"/>
    <parent link="tool0"/>
    <child link="camera_mount"/>
  </joint>

  <link name="cutter">
    <visual>
      <origin rpy="0 0 0" xyz="0 0 0.006"/>
      <geometry>
        <mesh filename="/home/main/python/pybullet/robots/ur5e/visual/new_cutter.dae" scale="1.0 1.0 1.0"/>
      </geometry>
      <material name="LightGrey"/>
    </visual>


        <!-- Tool/cutter collision-->

        <!-- Extra width on the end effector - This one is barely necessary, would never have a collision here -->
<!--        <collision>-->
<!--          <origin rpy="0 0 0" xyz="0 0 0.016" />-->
<!--          <geometry>-->
<!--            <cylinder radius="0.035" length="0.02" />-->
<!--          </geometry>-->
<!--        </collision>-->

        <!-- Cylinder for t
        he tool as a whole -->
<!--        <collision>-->
<!--          <origin xyz="-0.09 -0.01437 -0.01781" rpy="0 0 0" />-->
<!--          <geometry>-->
<!--            <cylinder radius="0.035" length="0.310" />-->
<!--          </geometry>-->
<!--        </collision>-->

        <!-- Box for the battery pack thing -->
        <collision>
              <origin xyz="-0.09197 -0.01500 -0.15356" rpy="0 0 0" />
              <geometry>
                <box size="0.07 0.084 0.06" />
              </geometry>
        </collision>

<!--        &lt;!&ndash; Updated cylinder - drawn to be thinner, more precise &ndash;&gt;-->
        <collision>
          <origin xyz="-0.09215 0 -0.0120" rpy="0 0 0" />
          <geometry>
            <cylinder radius="0.021" length="0.230" />
          </geometry>
        </collision>

        <!-- Boxes for the clamp - Tightly drawn -->

        <collision>
              <origin xyz="-0.08340 0 -0.03650" rpy="0 0 0" />
              <geometry>
                <box size="0.072 0.084 0.04" />
              </geometry>
        </collision>

        <collision>
              <origin xyz="-0.05740 0 -0.014" rpy="0 0 0" />
              <geometry>
                <box size="0.02 0.05 0.08" />
              </geometry>
        </collision>




    <inertial>
      <origin rpy="0 0 0" xyz="1.0E-08 1.0E-08 1.0E-08"/>
      <mass value="1.0E-08"/>
      <inertia ixx="1.0E-08" ixy="1.0E-08" ixz="1.0E-08" iyy="1.0E-08" iyz="1.0E-08" izz="1.0E-08"/>
    </inertial>
  </link>
  <joint name="cutter" type="fixed">
      <origin rpy="0 0 0" xyz="0 0 0"/>
    <axis xyz="0 0 1"/>
    <parent link="camera_mount"/>
    <child link="cutter"/>
  </joint>
  <link name="endpoint">
    <visual>
      <origin rpy="0 0 0" xyz="0 0 0"/>
      <geometry>
        <sphere radius="0.002" />
      </geometry>
      <material name="red">
        <color rgba="1 0 0 1" />
      </material>
    </visual>
  </link>
  <joint name="endpoint" type="fixed">
<!--    <origin rpy="0 0 0" xyz="0 0.09721 0.24210"/>  &lt;!&ndash; Left down out &ndash;&gt;-->
<!--    <origin rpy="0 0 0" xyz="-0.00425 0.08971 0.24210"/> &lt;!&ndash;USE THIS ONE IF THE IK FOR BELOW DOESNT DO BETTER&ndash;&gt;-->
    <origin rpy="0 0 3.14159" xyz="-0.09286 -0.00511 0.09707"/>

    <axis xyz="0 0 1"/>
    <parent link="cutter"/>
    <child link="endpoint"/>
  </joint>
  <link name="cutpoint">
    <visual>
      <origin rpy="0 0 0" xyz="0.0 0.0 0.0"/>
      <geometry>
        <sphere radius="0.006" />
      </geometry>
      <material name="green">
        <color rgba="0 1 0 1" />
      </material>
    </visual>
  </link>
  <joint name="cutpoint" type="fixed">
    <origin rpy="0 0 0" xyz="0 0 0"/>  <!-- Left down out -->
    <parent link="endpoint"/>
    <child link="cutpoint"/>
  </joint>
<!--  <link name="cutter_obst">-->
<!--    <collision>-->
<!--      <origin rpy="0 0 0" xyz="-0.008 -0.13 -0.28"/>-->
<!--      <geometry>-->
<!--        <box size="0.1 0.145 0.15"/>-->
<!--      </geometry>-->
<!--    </collision>-->
<!--    <inertial>-->
<!--      <origin rpy="0 0 0" xyz="1.0E-08 1.0E-08 1.0E-08"/>-->
<!--      <mass value="1.0E-08"/>-->
<!--      <inertia ixx="1.0E-08" ixy="1.0E-08" ixz="1.0E-08" iyy="1.0E-08" iyz="1.0E-08" izz="1.0E-08"/>-->
<!--    </inertial>-->
<!--  </link>-->
<!--  <joint name="cutter_obst" type="fixed">-->
<!--      <origin rpy="0 0 0" xyz="0 0.093 0.213"/>-->
<!--    <axis xyz="0 0 1"/>-->
<!--    <parent link="tool0"/>-->
<!--    <child link="cutter_obst"/>-->
<!--  </joint>-->
  <link name="world"/>
  <joint name="world_joint" type="fixed">
    <parent link="world"/>
    <child link="mount_base"/>
    <origin rpy="0.0 0.0 0.0" xyz="0.0 0.0 0.0"/>
  </joint>
</robot>

